<robot name="onshape">
<link name="l0">
<visual>
<origin xyz="1.3877787807814456755e-17 0 -0.020000000000000017764" rpy="0 -0 0" />
<geometry>
<mesh filename="package:///l0.stl"/>
</geometry>
<material name="l0_material">
<color rgba="0.30196078431372547213 0.30196078431372547213 0.30196078431372547213 1.0"/>
</material>
</visual>
<collision>
<origin xyz="1.3877787807814456755e-17 0 -0.020000000000000017764" rpy="0 -0 0" />
<geometry>
<mesh filename="package:///l0.stl"/>
</geometry>
</collision>
<inertial>
<origin xyz="4.0801131696625522079e-18 -8.1602263393251028751e-18 0.044999999999999984457" rpy="0 0 0"/>
<mass value="27.910676280822446671" />
<inertia ixx="0.10990388901602400618" ixy="0"  ixz="0" iyy="0.10990388901602400618" iyz="0" izz="0.18212836505293772404" />
</inertial>
</link>

<link name="l1">
<visual>
<origin xyz="0 -4.5924254968025751432e-18 0.11000000000000000056" rpy="3.141592653589793116 -0 -3.4509216026579128405e-67" />
<geometry>
<mesh filename="package:///l1.stl"/>
</geometry>
<material name="l1_material">
<color rgba="0.30196078431372547213 0.30196078431372547213 0.30196078431372547213 1.0"/>
</material>
</visual>
<collision>
<origin xyz="0 -4.5924254968025751432e-18 0.11000000000000000056" rpy="3.141592653589793116 -0 -3.4509216026579128405e-67" />
<geometry>
<mesh filename="package:///l1.stl"/>
</geometry>
</collision>
<inertial>
<origin xyz="-4.5394141761299505579e-19 1.8971629052710264345e-07 -0.048596791911239153872" rpy="0 0 0"/>
<mass value="13.447711806464674567" />
<inertia ixx="0.029151316769208391461" ixy="-2.0119770447175348556e-68"  ixz="-4.7457267005976811719e-74" iyy="0.029151283995942401522" iyz="1.3752055963645184083e-07" izz="0.036931024403735926431" />
</inertial>
</link>

<link name="l2">
<visual>
<origin xyz="1.6653345369377348106e-16 -0.20999999999999996447 -0.012500000000000000694" rpy="-1.570796326794896558 -9.8913101551933048603e-34 3.5935856290587473033e-18" />
<geometry>
<mesh filename="package:///l2.stl"/>
</geometry>
<material name="l2_material">
<color rgba="0.30196078431372547213 0.30196078431372547213 0.30196078431372547213 1.0"/>
</material>
</visual>
<collision>
<origin xyz="1.6653345369377348106e-16 -0.20999999999999996447 -0.012500000000000000694" rpy="-1.570796326794896558 -9.8913101551933048603e-34 3.5935856290587473033e-18" />
<geometry>
<mesh filename="package:///l2.stl"/>
</geometry>
</collision>
<inertial>
<origin xyz="4.2299004581806097438e-18 0.17500000000000004441 -0.012500000000000000694" rpy="0 0 0"/>
<mass value="3.3373406335618427399" />
<inertia ixx="0.032438698118407188753" ixy="2.9345327120449318364e-20"  ixz="2.3902283554404245508e-34" iyy="0.00084992367319783638461" iyz="5.9818544542622583579e-35" izz="0.032940982142275677946" />
</inertial>
</link>

<link name="l3">
<visual>
<origin xyz="-0.00099999999999994537703 -0.58400000000000007461 -0.012500000000000000694" rpy="-1.570796326794896558 7.5202483390227170023e-33 -7.2188065457040813159e-18" />
<geometry>
<mesh filename="package:///l3.stl"/>
</geometry>
<material name="l3_material">
<color rgba="0.30196078431372547213 0.30196078431372547213 0.30196078431372547213 1.0"/>
</material>
</visual>
<collision>
<origin xyz="-0.00099999999999994537703 -0.58400000000000007461 -0.012500000000000000694" rpy="-1.570796326794896558 7.5202483390227170023e-33 -7.2188065457040813159e-18" />
<geometry>
<mesh filename="package:///l3.stl"/>
</geometry>
</collision>
<inertial>
<origin xyz="-0.00099999999999995513485 0.20099999999999984546 -0.012500000000000002429" rpy="0 0 0"/>
<mass value="4.3185906335617918472" />
<inertia ixx="0.070055563123260819469" ixy="-4.1485865025837278156e-19"  ixz="-1.3038935140939137937e-33" iyy="0.0011054575273644713304" iyz="7.5303727120694504186e-34" izz="0.070711167459629270526" />
</inertial>
</link>

<link name="l4">
<visual>
<origin xyz="-3.3457801416562711371e-17 5.5511151231257827021e-17 1.0100367726601677809" rpy="3.141592653589793116 7.8499306092441216018e-33 5.1931089535010233675e-31" />
<geometry>
<mesh filename="package:///l4.stl"/>
</geometry>
<material name="l4_material">
<color rgba="0.72941176470588231506 0.25098039215686274161 0.10588235294117646912 1.0"/>
</material>
</visual>
<collision>
<origin xyz="-3.3457801416562711371e-17 5.5511151231257827021e-17 1.0100367726601677809" rpy="3.141592653589793116 7.8499306092441216018e-33 5.1931089535010233675e-31" />
<geometry>
<mesh filename="package:///l4.stl"/>
</geometry>
</collision>
<inertial>
<origin xyz="-2.8472777840028952934e-16 2.6105420368755241908e-17 -0.084963686266581683881" rpy="0 0 0"/>
<mass value="4.4544598019896355368" />
<inertia ixx="0.0082777408652067990119" ixy="7.6102194464477224373e-33"  ixz="-1.1449301624892783258e-33" iyy="0.016091649189825526362" iyz="-1.9448123708641509768e-19" izz="0.0082779145539926476949" />
</inertial>
</link>

<joint name="j3" type="revolute">
<origin xyz="-0.00099999999999983435472 0.42599999999999993427 -0.012500000000000002429" rpy="1.570796326794896558 -1.5707963267948936714 0" />
<parent link="l3" />
<child link="l4" />
<axis xyz="0 0 1"/>
<limit effort="1" velocity="20" />
<joint_properties friction="0.0"/>
</joint>

<joint name="j2" type="revolute">
<origin xyz="0.0010000000000004310996 0.32600000000000012301 0" rpy="-4.4418730579212722599e-17 1.4933327212415319267e-16 -2.625332535053612748" />
<parent link="l2" />
<child link="l3" />
<axis xyz="0 0 1"/>
<limit effort="1" velocity="20" />
<joint_properties friction="0.0"/>
</joint>

<joint name="j1" type="revolute">
<origin xyz="-1.6692094174101975211e-17 0.012499999999999981612 -0.10249999999999999389" rpy="-1.570796326794896558 0.45280859007778573311 -3.2897652120393876511e-17" />
<parent link="l1" />
<child link="l2" />
<axis xyz="0 0 1"/>
<limit effort="1" velocity="20" />
<joint_properties friction="0.0"/>
</joint>

<joint name="j0" type="revolute">
<origin xyz="2.8143063662875404109e-18 -1.3722147524374453319e-17 0.089999999999999982792" rpy="3.141592653589793116 1.4945216368444943651e-31 -8.6305549185138863235e-50" />
<parent link="l0" />
<child link="l1" />
<axis xyz="0 0 1"/>
<limit effort="1" velocity="20" />
<joint_properties friction="0.0"/>
</joint>


</robot>
